<?xml version="1.0" ?>
<robot name="arceus_minimal_sim" xmlns:xacro="http://www.ros.org/wiki/xacro">

<xacro:include filename="$(find arceus_minimal_sim_description)/urdf/materials.xacro" />
<xacro:include filename="$(find arceus_minimal_sim_description)/urdf/arceus_minimal_sim.trans" />
<xacro:include filename="$(find arceus_minimal_sim_description)/urdf/arceus_minimal_sim.gazebo" />
<link name="base_link">
  <inertial>
    <origin xyz="-0.14237618092258633 0.0449304506595644 0.10785901944419286" rpy="0 0 0"/>
    <mass value="0.8785437294227729"/>
    <inertia ixx="0.006006" iyy="0.002942" izz="0.004066" ixy="-2e-06" iyz="-5e-06" ixz="-2.7e-05"/>
  </inertial>
  <visual>
    <origin xyz="0 0 0" rpy="0 0 0"/>
    <geometry>
      <mesh filename="file://$(find arceus_minimal_sim_description)/meshes/base_link.stl" scale="0.001 0.001 0.001"/>
    </geometry>
    <material name="silver"/>
  </visual>
  <collision>
    <origin xyz="0 0 0" rpy="0 0 0"/>
    <geometry>
      <mesh filename="file://$(find arceus_minimal_sim_description)/meshes/base_link.stl" scale="0.001 0.001 0.001"/>
    </geometry>
  </collision>
</link>

<link name="back_left_motor_1">
  <inertial>
    <origin xyz="-3.628653647801128e-07 -1.6609408964862737e-07 0.010782694472912857" rpy="0 0 0"/>
    <mass value="0.07248964565668625"/>
    <inertia ixx="6e-06" iyy="6e-06" izz="8e-06" ixy="-0.0" iyz="-0.0" ixz="-0.0"/>
  </inertial>
  <visual>
    <origin xyz="-0.018723 0.112956 -0.264669" rpy="0 0 0"/>
    <geometry>
      <mesh filename="file://$(find arceus_minimal_sim_description)/meshes/back_left_motor_1.stl" scale="0.001 0.001 0.001"/>
    </geometry>
    <material name="silver"/>
  </visual>
  <collision>
    <origin xyz="-0.018723 0.112956 -0.264669" rpy="0 0 0"/>
    <geometry>
      <mesh filename="file://$(find arceus_minimal_sim_description)/meshes/back_left_motor_1.stl" scale="0.001 0.001 0.001"/>
    </geometry>
  </collision>
</link>

<link name="prop_lb_1">
  <inertial>
    <origin xyz="-6.104010574353724e-07 1.6163309915773194e-06 -0.0019481551449321843" rpy="0 0 0"/>
    <mass value="0.05057573223968042"/>
    <inertia ixx="0.000193" iyy="1e-06" izz="0.000194" ixy="6e-06" iyz="0.0" ixz="-0.0"/>
  </inertial>
  <visual>
    <origin xyz="-0.018723 0.112956 -0.299369" rpy="0 0 0"/>
    <geometry>
      <mesh filename="file://$(find arceus_minimal_sim_description)/meshes/prop_lb_1.stl" scale="0.001 0.001 0.001"/>
    </geometry>
    <material name="silver"/>
  </visual>
  <collision>
    <origin xyz="-0.018723 0.112956 -0.299369" rpy="0 0 0"/>
    <geometry>
      <mesh filename="file://$(find arceus_minimal_sim_description)/meshes/prop_lb_1.stl" scale="0.001 0.001 0.001"/>
    </geometry>
  </collision>
</link>

<link name="prop_rb_1">
  <inertial>
    <origin xyz="-1.0305089801973533e-07 -1.3908305988852288e-06 -0.0019481551449322954" rpy="0 0 0"/>
    <mass value="0.05057573223968037"/>
    <inertia ixx="0.000193" iyy="1e-06" izz="0.000194" ixy="6e-06" iyz="-0.0" ixz="-0.0"/>
  </inertial>
  <visual>
    <origin xyz="-0.018723 -0.204287 -0.299369" rpy="0 0 0"/>
    <geometry>
      <mesh filename="file://$(find arceus_minimal_sim_description)/meshes/prop_rb_1.stl" scale="0.001 0.001 0.001"/>
    </geometry>
    <material name="silver"/>
  </visual>
  <collision>
    <origin xyz="-0.018723 -0.204287 -0.299369" rpy="0 0 0"/>
    <geometry>
      <mesh filename="file://$(find arceus_minimal_sim_description)/meshes/prop_rb_1.stl" scale="0.001 0.001 0.001"/>
    </geometry>
  </collision>
</link>

<link name="prop_lf_1">
  <inertial>
    <origin xyz="1.5200486297439753e-07 -1.032401052064591e-06 -0.0019481549825060562" rpy="0 0 0"/>
    <mass value="0.05057573223968104"/>
    <inertia ixx="0.000193" iyy="1e-06" izz="0.000194" ixy="6e-06" iyz="0.0" ixz="0.0"/>
  </inertial>
  <visual>
    <origin xyz="0.300396 0.112956 -0.299369" rpy="0 0 0"/>
    <geometry>
      <mesh filename="file://$(find arceus_minimal_sim_description)/meshes/prop_lf_1.stl" scale="0.001 0.001 0.001"/>
    </geometry>
    <material name="silver"/>
  </visual>
  <collision>
    <origin xyz="0.300396 0.112956 -0.299369" rpy="0 0 0"/>
    <geometry>
      <mesh filename="file://$(find arceus_minimal_sim_description)/meshes/prop_lf_1.stl" scale="0.001 0.001 0.001"/>
    </geometry>
  </collision>
</link>

<link name="prop_rf_1">
  <inertial>
    <origin xyz="-3.5534529696512607e-07 1.2579014433411473e-06 -0.0024481551449320738" rpy="0 0 0"/>
    <mass value="0.05057573223968031"/>
    <inertia ixx="0.000193" iyy="1e-06" izz="0.000194" ixy="6e-06" iyz="-0.0" ixz="0.0"/>
  </inertial>
  <visual>
    <origin xyz="0.300396 -0.204287 -0.299219" rpy="0 0 0"/>
    <geometry>
      <mesh filename="file://$(find arceus_minimal_sim_description)/meshes/prop_rf_1.stl" scale="0.001 0.001 0.001"/>
    </geometry>
    <material name="silver"/>
  </visual>
  <collision>
    <origin xyz="0.300396 -0.204287 -0.299219" rpy="0 0 0"/>
    <geometry>
      <mesh filename="file://$(find arceus_minimal_sim_description)/meshes/prop_rf_1.stl" scale="0.001 0.001 0.001"/>
    </geometry>
  </collision>
</link>

<link name="front_left_motor_1">
  <inertial>
    <origin xyz="-4.5336457465960933e-07 -1.6609408963474959e-07 0.01078269447291308" rpy="0 0 0"/>
    <mass value="0.07248964565668688"/>
    <inertia ixx="6e-06" iyy="6e-06" izz="8e-06" ixy="-0.0" iyz="-0.0" ixz="-0.0"/>
  </inertial>
  <visual>
    <origin xyz="0.300396 0.112956 -0.264669" rpy="0 0 0"/>
    <geometry>
      <mesh filename="file://$(find arceus_minimal_sim_description)/meshes/front_left_motor_1.stl" scale="0.001 0.001 0.001"/>
    </geometry>
    <material name="silver"/>
  </visual>
  <collision>
    <origin xyz="0.300396 0.112956 -0.264669" rpy="0 0 0"/>
    <geometry>
      <mesh filename="file://$(find arceus_minimal_sim_description)/meshes/front_left_motor_1.stl" scale="0.001 0.001 0.001"/>
    </geometry>
  </collision>
</link>

<link name="front_right_motor_1">
  <inertial>
    <origin xyz="-4.533645747151205e-07 -1.81000189086733e-07 0.010782694472912968" rpy="0 0 0"/>
    <mass value="0.07248964565668695"/>
    <inertia ixx="6e-06" iyy="6e-06" izz="8e-06" ixy="-0.0" iyz="-0.0" ixz="-0.0"/>
  </inertial>
  <visual>
    <origin xyz="0.300396 -0.204287 -0.264669" rpy="0 0 0"/>
    <geometry>
      <mesh filename="file://$(find arceus_minimal_sim_description)/meshes/front_right_motor_1.stl" scale="0.001 0.001 0.001"/>
    </geometry>
    <material name="silver"/>
  </visual>
  <collision>
    <origin xyz="0.300396 -0.204287 -0.264669" rpy="0 0 0"/>
    <geometry>
      <mesh filename="file://$(find arceus_minimal_sim_description)/meshes/front_right_motor_1.stl" scale="0.001 0.001 0.001"/>
    </geometry>
  </collision>
</link>

<link name="back_right_motor_1">
  <inertial>
    <origin xyz="-3.628653650333824e-07 -1.810001889479551e-07 0.010782694472913024" rpy="0 0 0"/>
    <mass value="0.07248964565668638"/>
    <inertia ixx="6e-06" iyy="6e-06" izz="8e-06" ixy="-0.0" iyz="-0.0" ixz="-0.0"/>
  </inertial>
  <visual>
    <origin xyz="-0.018723 -0.204287 -0.264669" rpy="0 0 0"/>
    <geometry>
      <mesh filename="file://$(find arceus_minimal_sim_description)/meshes/back_right_motor_1.stl" scale="0.001 0.001 0.001"/>
    </geometry>
    <material name="silver"/>
  </visual>
  <collision>
    <origin xyz="-0.018723 -0.204287 -0.264669" rpy="0 0 0"/>
    <geometry>
      <mesh filename="file://$(find arceus_minimal_sim_description)/meshes/back_right_motor_1.stl" scale="0.001 0.001 0.001"/>
    </geometry>
  </collision>
</link>

<link name="upper_half_1">
  <inertial>
    <origin xyz="0.04050689765983606 0.05872849012000784 0.00828636949920536" rpy="0 0 0"/>
    <mass value="2.012714895401499"/>
    <inertia ixx="0.0164" iyy="0.015346" izz="0.030565" ixy="0.0" iyz="-1.1e-05" ixz="-8e-06"/>
  </inertial>
  <visual>
    <origin xyz="0.181566 0.013312 -0.237319" rpy="0 0 0"/>
    <geometry>
      <mesh filename="file://$(find arceus_minimal_sim_description)/meshes/upper_half_1.stl" scale="0.001 0.001 0.001"/>
    </geometry>
    <material name="silver"/>
  </visual>
  <collision>
    <origin xyz="0.181566 0.013312 -0.237319" rpy="0 0 0"/>
    <geometry>
      <mesh filename="file://$(find arceus_minimal_sim_description)/meshes/upper_half_1.stl" scale="0.001 0.001 0.001"/>
    </geometry>
  </collision>
</link>

<link name="right_wheel_1">
  <inertial>
    <origin xyz="1.340995869347772e-07 0.006021921864224317 1.789825375062004e-07" rpy="0 0 0"/>
    <mass value="0.15898302010496543"/>
    <inertia ixx="0.000126" iyy="0.000234" izz="0.000126" ixy="-0.0" iyz="-0.0" ixz="-0.0"/>
  </inertial>
  <visual>
    <origin xyz="0.143159 -0.181695 -0.052889" rpy="0 0 0"/>
    <geometry>
      <mesh filename="file://$(find arceus_minimal_sim_description)/meshes/right_wheel_1.stl" scale="0.001 0.001 0.001"/>
    </geometry>
    <material name="silver"/>
  </visual>
  <collision>
    <origin xyz="0.143159 -0.181695 -0.052889" rpy="0 0 0"/>
    <geometry>
      <mesh filename="file://$(find arceus_minimal_sim_description)/meshes/right_wheel_1.stl" scale="0.001 0.001 0.001"/>
    </geometry>
  </collision>
</link>

<link name="left_wheel_1">
  <inertial>
    <origin xyz="1.3427284301092968e-07 -0.00602142239605484 -2.1447608501007354e-07" rpy="0 0 0"/>
    <mass value="0.15898302010496498"/>
    <inertia ixx="0.000126" iyy="0.000234" izz="0.000126" ixy="0.0" iyz="-0.0" ixz="-0.0"/>
  </inertial>
  <visual>
    <origin xyz="0.143409 0.091337 -0.052466" rpy="0 0 0"/>
    <geometry>
      <mesh filename="file://$(find arceus_minimal_sim_description)/meshes/left_wheel_1.stl" scale="0.001 0.001 0.001"/>
    </geometry>
    <material name="silver"/>
  </visual>
  <collision>
    <origin xyz="0.143409 0.091337 -0.052466" rpy="0 0 0"/>
    <geometry>
      <mesh filename="file://$(find arceus_minimal_sim_description)/meshes/left_wheel_1.stl" scale="0.001 0.001 0.001"/>
    </geometry>
  </collision>
</link>

<joint name="Rigid 1" type="fixed">
  <origin xyz="0.200289 -0.099644 0.02735" rpy="0 0 0"/>
  <parent link="upper_half_1"/>
  <child link="back_left_motor_1"/>
</joint>

<joint name="Revolute 2" type="continuous">
  <origin xyz="0.0 0.0 0.0347" rpy="0 0 0"/>
  <parent link="back_left_motor_1"/>
  <child link="prop_lb_1"/>
  <axis xyz="0.0 0.0 1.0"/>
</joint>

<joint name="Revolute 3" type="continuous">
  <origin xyz="0.0 0.0 0.0347" rpy="0 0 0"/>
  <parent link="back_right_motor_1"/>
  <child link="prop_rb_1"/>
  <axis xyz="-0.0 -0.0 1.0"/>
</joint>

<joint name="Revolute 4" type="continuous">
  <origin xyz="0.0 0.0 0.0347" rpy="0 0 0"/>
  <parent link="front_left_motor_1"/>
  <child link="prop_lf_1"/>
  <axis xyz="-0.0 -0.0 1.0"/>
</joint>

<joint name="Revolute 5" type="continuous">
  <origin xyz="0.0 0.0 0.03455" rpy="0 0 0"/>
  <parent link="front_right_motor_1"/>
  <child link="prop_rf_1"/>
  <axis xyz="-0.0 -0.0 1.0"/>
</joint>

<joint name="Rigid 6" type="fixed">
  <origin xyz="-0.11883 -0.099644 0.02735" rpy="0 0 0"/>
  <parent link="upper_half_1"/>
  <child link="front_left_motor_1"/>
</joint>

<joint name="Rigid 7" type="fixed">
  <origin xyz="-0.11883 0.217599 0.02735" rpy="0 0 0"/>
  <parent link="upper_half_1"/>
  <child link="front_right_motor_1"/>
</joint>

<joint name="Rigid 8" type="fixed">
  <origin xyz="0.200289 0.217599 0.02735" rpy="0 0 0"/>
  <parent link="upper_half_1"/>
  <child link="back_right_motor_1"/>
</joint>

<joint name="Rigid 9" type="fixed">
  <origin xyz="-0.181566 -0.013312 0.237319" rpy="0 0 0"/>
  <parent link="base_link"/>
  <child link="upper_half_1"/>
</joint>

<joint name="Revolute 10" type="continuous">
  <origin xyz="-0.143159 0.181695 0.052889" rpy="0 0 0"/>
  <parent link="base_link"/>
  <child link="right_wheel_1"/>
  <axis xyz="0.0 1.0 -0.0"/>
</joint>

<joint name="Revolute 11" type="continuous">
  <origin xyz="-0.143409 -0.091337 0.052466" rpy="0 0 0"/>
  <parent link="base_link"/>
  <child link="left_wheel_1"/>
  <axis xyz="0.0 -1.0 0.0"/>
</joint>

</robot>
